<?xml version="1.0" ?>
<!-- =================================================================================== -->
<!-- |    This document was autogenerated by xacro from /home/ubuntu/Downloads/assembly_simple_description/urdf/assembly_simple.xacro | -->
<!-- |    EDITING THIS FILE BY HAND IS NOT RECOMMENDED                                 | -->
<!-- =================================================================================== -->
<robot name="assembly_simple">
  <material name="silver">
    <color rgba="0.700 0.700 0.700 1.000"/>
  </material>
  <transmission name="Revolute 1_tran">
    <type>transmission_interface/SimpleTransmission</type>
    <joint name="Revolute 1">
      <hardwareInterface>hardware_interface/EffortJointInterface</hardwareInterface>
    </joint>
    <actuator name="Revolute 1_actr">
      <hardwareInterface>hardware_interface/EffortJointInterface</hardwareInterface>
      <mechanicalReduction>1</mechanicalReduction>
    </actuator>
  </transmission>
  <transmission name="Revolute 2_tran">
    <type>transmission_interface/SimpleTransmission</type>
    <joint name="Revolute 2">
      <hardwareInterface>hardware_interface/EffortJointInterface</hardwareInterface>
    </joint>
    <actuator name="Revolute 2_actr">
      <hardwareInterface>hardware_interface/EffortJointInterface</hardwareInterface>
      <mechanicalReduction>1</mechanicalReduction>
    </actuator>
  </transmission>
  <transmission name="Revolute 3_tran">
    <type>transmission_interface/SimpleTransmission</type>
    <joint name="Revolute 3">
      <hardwareInterface>hardware_interface/EffortJointInterface</hardwareInterface>
    </joint>
    <actuator name="Revolute 3_actr">
      <hardwareInterface>hardware_interface/EffortJointInterface</hardwareInterface>
      <mechanicalReduction>1</mechanicalReduction>
    </actuator>
  </transmission>
  <transmission name="Revolute 4_tran">
    <type>transmission_interface/SimpleTransmission</type>
    <joint name="Revolute 4">
      <hardwareInterface>hardware_interface/EffortJointInterface</hardwareInterface>
    </joint>
    <actuator name="Revolute 4_actr">
      <hardwareInterface>hardware_interface/EffortJointInterface</hardwareInterface>
      <mechanicalReduction>1</mechanicalReduction>
    </actuator>
  </transmission>
  <transmission name="Revolute 5_tran">
    <type>transmission_interface/SimpleTransmission</type>
    <joint name="Revolute 5">
      <hardwareInterface>hardware_interface/EffortJointInterface</hardwareInterface>
    </joint>
    <actuator name="Revolute 5_actr">
      <hardwareInterface>hardware_interface/EffortJointInterface</hardwareInterface>
      <mechanicalReduction>1</mechanicalReduction>
    </actuator>
  </transmission>
  <transmission name="Revolute 6_tran">
    <type>transmission_interface/SimpleTransmission</type>
    <joint name="Revolute 6">
      <hardwareInterface>hardware_interface/EffortJointInterface</hardwareInterface>
    </joint>
    <actuator name="Revolute 6_actr">
      <hardwareInterface>hardware_interface/EffortJointInterface</hardwareInterface>
      <mechanicalReduction>1</mechanicalReduction>
    </actuator>
  </transmission>
  <transmission name="Revolute 7_tran">
    <type>transmission_interface/SimpleTransmission</type>
    <joint name="Revolute 7">
      <hardwareInterface>hardware_interface/EffortJointInterface</hardwareInterface>
    </joint>
    <actuator name="Revolute 7_actr">
      <hardwareInterface>hardware_interface/EffortJointInterface</hardwareInterface>
      <mechanicalReduction>1</mechanicalReduction>
    </actuator>
  </transmission>
  <transmission name="Revolute 8_tran">
    <type>transmission_interface/SimpleTransmission</type>
    <joint name="Revolute 8">
      <hardwareInterface>hardware_interface/EffortJointInterface</hardwareInterface>
    </joint>
    <actuator name="Revolute 8_actr">
      <hardwareInterface>hardware_interface/EffortJointInterface</hardwareInterface>
      <mechanicalReduction>1</mechanicalReduction>
    </actuator>
  </transmission>
  <transmission name="Revolute 9_tran">
    <type>transmission_interface/SimpleTransmission</type>
    <joint name="Revolute 9">
      <hardwareInterface>hardware_interface/EffortJointInterface</hardwareInterface>
    </joint>
    <actuator name="Revolute 9_actr">
      <hardwareInterface>hardware_interface/EffortJointInterface</hardwareInterface>
      <mechanicalReduction>1</mechanicalReduction>
    </actuator>
  </transmission>
  <transmission name="Revolute 10_tran">
    <type>transmission_interface/SimpleTransmission</type>
    <joint name="Revolute 10">
      <hardwareInterface>hardware_interface/EffortJointInterface</hardwareInterface>
    </joint>
    <actuator name="Revolute 10_actr">
      <hardwareInterface>hardware_interface/EffortJointInterface</hardwareInterface>
      <mechanicalReduction>1</mechanicalReduction>
    </actuator>
  </transmission>
  <transmission name="Revolute 11_tran">
    <type>transmission_interface/SimpleTransmission</type>
    <joint name="Revolute 11">
      <hardwareInterface>hardware_interface/EffortJointInterface</hardwareInterface>
    </joint>
    <actuator name="Revolute 11_actr">
      <hardwareInterface>hardware_interface/EffortJointInterface</hardwareInterface>
      <mechanicalReduction>1</mechanicalReduction>
    </actuator>
  </transmission>
  <transmission name="Revolute 12_tran">
    <type>transmission_interface/SimpleTransmission</type>
    <joint name="Revolute 12">
      <hardwareInterface>hardware_interface/EffortJointInterface</hardwareInterface>
    </joint>
    <actuator name="Revolute 12_actr">
      <hardwareInterface>hardware_interface/EffortJointInterface</hardwareInterface>
      <mechanicalReduction>1</mechanicalReduction>
    </actuator>
  </transmission>
  <gazebo>
    <plugin filename="libgazebo_ros_control.so" name="control"/>
  </gazebo>
  <gazebo reference="base_link">
    <material>Gazebo/Silver</material>
    <mu1>0.2</mu1>
    <mu2>0.2</mu2>
    <selfCollide>true</selfCollide>
    <gravity>true</gravity>
  </gazebo>
  <gazebo reference="assembly_simplyv3_backup_hip_L_simple_v2_v1_1">
    <material>Gazebo/Silver</material>
    <mu1>0.2</mu1>
    <mu2>0.2</mu2>
    <selfCollide>true</selfCollide>
  </gazebo>
  <gazebo reference="assembly_simplyv3_backup_hip_L_simple_v2_Mirror__Mirror__v1_1">
    <material>Gazebo/Silver</material>
    <mu1>0.2</mu1>
    <mu2>0.2</mu2>
    <selfCollide>true</selfCollide>
  </gazebo>
  <gazebo reference="assembly_simplyv3_backup_hip_L_simple_v2_Mirror__v1_1">
    <material>Gazebo/Silver</material>
    <mu1>0.2</mu1>
    <mu2>0.2</mu2>
    <selfCollide>true</selfCollide>
  </gazebo>
  <gazebo reference="assembly_simplyv3_backup_hip_L_simple_v2_Mirror___1__v1_1">
    <material>Gazebo/Silver</material>
    <mu1>0.2</mu1>
    <mu2>0.2</mu2>
    <selfCollide>true</selfCollide>
  </gazebo>
  <gazebo reference="assembly_simplyv3_backup_Component6_v1_1">
    <material>Gazebo/Silver</material>
    <mu1>0.2</mu1>
    <mu2>0.2</mu2>
    <selfCollide>true</selfCollide>
  </gazebo>
  <gazebo reference="assembly_simplyv3_backup_Component6_Mirror__v1_1">
    <material>Gazebo/Silver</material>
    <mu1>0.2</mu1>
    <mu2>0.2</mu2>
    <selfCollide>true</selfCollide>
  </gazebo>
  <gazebo reference="assembly_simplyv3_backup_Component6_Mirror__Mirror__v1_1">
    <material>Gazebo/Silver</material>
    <mu1>0.2</mu1>
    <mu2>0.2</mu2>
    <selfCollide>true</selfCollide>
  </gazebo>
  <gazebo reference="assembly_simplyv3_backup_Component6_Mirror___1__v1_1">
    <material>Gazebo/Silver</material>
    <mu1>0.2</mu1>
    <mu2>0.2</mu2>
    <selfCollide>true</selfCollide>
  </gazebo>
  <gazebo reference="assembly_simplyv3_backup_lowerleg_left_v2_v1_1">
    <material>Gazebo/Silver</material>
    <mu1>0.2</mu1>
    <mu2>0.2</mu2>
    <selfCollide>true</selfCollide>
  </gazebo>
  <gazebo reference="assembly_simplyv3_backup_lowerleg_left_v2_Mirror__v1_1">
    <material>Gazebo/Silver</material>
    <mu1>0.2</mu1>
    <mu2>0.2</mu2>
    <selfCollide>true</selfCollide>
  </gazebo>
  <gazebo reference="assembly_simplyv3_backup_lowerleg_left_v2_Mirror___1__v1_1">
    <material>Gazebo/Silver</material>
    <mu1>0.2</mu1>
    <mu2>0.2</mu2>
    <selfCollide>true</selfCollide>
  </gazebo>
  <gazebo reference="assembly_simplyv3_backup_lowerleg_left_v2_Mirror__Mirror__v1_1">
    <material>Gazebo/Silver</material>
    <mu1>0.2</mu1>
    <mu2>0.2</mu2>
    <selfCollide>true</selfCollide>
  </gazebo>
  <link name="base_link">
    <inertial>
      <origin rpy="0 0 0" xyz="-4.01415715045929e-06 -0.0005363751487602584 0.01904486350731033"/>
      <mass value="0.06711365970673608"/>
      <inertia ixx="6.4e-05" ixy="-0.0" ixz="-0.0" iyy="4.2e-05" iyz="1e-06" izz="8.8e-05"/>
    </inertial>
    <visual>
      <origin rpy="0 0 0" xyz="0 0 0"/>
      <geometry>
        <mesh filename="/assembly_simple_description/meshes/base_link.obj" scale="0.001 0.001 0.001"/>
      </geometry>
      <material name="silver"/>
    </visual>
    <collision>
      <origin rpy="0 0 0" xyz="0 0 0"/>
      <geometry>
        <mesh filename="/assembly_simple_description/meshes/base_link.obj" scale="0.001 0.001 0.001"/>
      </geometry>
    </collision>
  </link>
  <link name="assembly_simplyv3_backup_hip_L_simple_v2_v1_1">
    <inertial>
      <origin rpy="0 0 0" xyz="0.0026471348660554762 0.008154605102083302 0.006021408043386009"/>
      <mass value="0.010651772434958885"/>
      <inertia ixx="1e-06" ixy="0.0" ixz="-0.0" iyy="1e-06" iyz="0.0" izz="1e-06"/>
    </inertial>
    <visual>
      <origin rpy="0 0 0" xyz="0.026925 -0.05165 -0.02138"/>
      <geometry>
        <mesh filename="/assembly_simple_description/meshes/assembly_simplyv3_backup_hip_L_simple_v2_v1_1.obj" scale="0.001 0.001 0.001"/>
      </geometry>
      <material name="silver"/>
    </visual>
    <collision>
      <origin rpy="0 0 0" xyz="0.026925 -0.05165 -0.02138"/>
      <geometry>
        <mesh filename="/assembly_simple_description/meshes/assembly_simplyv3_backup_hip_L_simple_v2_v1_1.obj" scale="0.001 0.001 0.001"/>
      </geometry>
    </collision>
  </link>
  <link name="assembly_simplyv3_backup_hip_L_simple_v2_Mirror__Mirror__v1_1">
    <inertial>
      <origin rpy="0 0 0" xyz="-0.0026471348660554762 -0.008154605102083302 0.006021408043386019"/>
      <mass value="0.010651772434958885"/>
      <inertia ixx="1e-06" ixy="0.0" ixz="0.0" iyy="1e-06" iyz="-0.0" izz="1e-06"/>
    </inertial>
    <visual>
      <origin rpy="0 0 0" xyz="-0.026925 0.05165 -0.02138"/>
      <geometry>
        <mesh filename="/assembly_simple_description/meshes/assembly_simplyv3_backup_hip_L_simple_v2_Mirror__Mirror__v1_1.obj" scale="0.001 0.001 0.001"/>
      </geometry>
      <material name="silver"/>
    </visual>
    <collision>
      <origin rpy="0 0 0" xyz="-0.026925 0.05165 -0.02138"/>
      <geometry>
        <mesh filename="/assembly_simple_description/meshes/assembly_simplyv3_backup_hip_L_simple_v2_Mirror__Mirror__v1_1.obj" scale="0.001 0.001 0.001"/>
      </geometry>
    </collision>
  </link>
  <link name="assembly_simplyv3_backup_hip_L_simple_v2_Mirror__v1_1">
    <inertial>
      <origin rpy="0 0 0" xyz="-0.002647134961283666 0.00815460508924732 0.006021408742554624"/>
      <mass value="0.010651772367412021"/>
      <inertia ixx="1e-06" ixy="-0.0" ixz="0.0" iyy="1e-06" iyz="0.0" izz="1e-06"/>
    </inertial>
    <visual>
      <origin rpy="0 0 0" xyz="-0.026925 -0.05165 -0.02138"/>
      <geometry>
        <mesh filename="/assembly_simple_description/meshes/assembly_simplyv3_backup_hip_L_simple_v2_Mirror__v1_1.obj" scale="0.001 0.001 0.001"/>
      </geometry>
      <material name="silver"/>
    </visual>
    <collision>
      <origin rpy="0 0 0" xyz="-0.026925 -0.05165 -0.02138"/>
      <geometry>
        <mesh filename="/assembly_simple_description/meshes/assembly_simplyv3_backup_hip_L_simple_v2_Mirror__v1_1.obj" scale="0.001 0.001 0.001"/>
      </geometry>
    </collision>
  </link>
  <link name="assembly_simplyv3_backup_hip_L_simple_v2_Mirror___1__v1_1">
    <inertial>
      <origin rpy="0 0 0" xyz="0.002647134961283666 -0.008154605089247341 0.006021408742554621"/>
      <mass value="0.010651772367412021"/>
      <inertia ixx="1e-06" ixy="-0.0" ixz="-0.0" iyy="1e-06" iyz="-0.0" izz="1e-06"/>
    </inertial>
    <visual>
      <origin rpy="0 0 0" xyz="0.026925 0.05165 -0.02138"/>
      <geometry>
        <mesh filename="/assembly_simple_description/meshes/assembly_simplyv3_backup_hip_L_simple_v2_Mirror___1__v1_1.obj" scale="0.001 0.001 0.001"/>
      </geometry>
      <material name="silver"/>
    </visual>
    <collision>
      <origin rpy="0 0 0" xyz="0.026925 0.05165 -0.02138"/>
      <geometry>
        <mesh filename="/assembly_simple_description/meshes/assembly_simplyv3_backup_hip_L_simple_v2_Mirror___1__v1_1.obj" scale="0.001 0.001 0.001"/>
      </geometry>
    </collision>
  </link>
  <link name="assembly_simplyv3_backup_Component6_v1_1">
    <inertial>
      <origin rpy="0 0 0" xyz="-0.0140979448138756 -0.031213531473714 8.43387692355535e-05"/>
      <mass value="0.012949528379146385"/>
      <inertia ixx="6e-06" ixy="-1e-06" ixz="0.0" iyy="1e-06" iyz="0.0" izz="7e-06"/>
    </inertial>
    <visual>
      <origin rpy="0 0 0" xyz="0.039485 -0.06105 -0.022478"/>
      <geometry>
        <mesh filename="/assembly_simple_description/meshes/assembly_simplyv3_backup_Component6_v1_1.obj" scale="0.001 0.001 0.001"/>
      </geometry>
      <material name="silver"/>
    </visual>
    <collision>
      <origin rpy="0 0 0" xyz="0.039485 -0.06105 -0.022478"/>
      <geometry>
        <mesh filename="/assembly_simple_description/meshes/assembly_simplyv3_backup_Component6_v1_1.obj" scale="0.001 0.001 0.001"/>
      </geometry>
    </collision>
  </link>
  <link name="assembly_simplyv3_backup_Component6_Mirror__v1_1">
    <inertial>
      <origin rpy="0 0 0" xyz="-0.014097947947670122 0.031213496015972925 8.433709991044133e-05"/>
      <mass value="0.012949520700092825"/>
      <inertia ixx="6e-06" ixy="1e-06" ixz="0.0" iyy="1e-06" iyz="-0.0" izz="7e-06"/>
    </inertial>
    <visual>
      <origin rpy="0 0 0" xyz="0.039485 0.06105 -0.022478"/>
      <geometry>
        <mesh filename="/assembly_simple_description/meshes/assembly_simplyv3_backup_Component6_Mirror__v1_1.obj" scale="0.001 0.001 0.001"/>
      </geometry>
      <material name="silver"/>
    </visual>
    <collision>
      <origin rpy="0 0 0" xyz="0.039485 0.06105 -0.022478"/>
      <geometry>
        <mesh filename="/assembly_simple_description/meshes/assembly_simplyv3_backup_Component6_Mirror__v1_1.obj" scale="0.001 0.001 0.001"/>
      </geometry>
    </collision>
  </link>
  <link name="assembly_simplyv3_backup_Component6_Mirror__Mirror__v1_1">
    <inertial>
      <origin rpy="0 0 0" xyz="0.014097944813875614 0.031213531473714008 8.433876923555697e-05"/>
      <mass value="0.012949528379146385"/>
      <inertia ixx="6e-06" ixy="-1e-06" ixz="-0.0" iyy="1e-06" iyz="-0.0" izz="7e-06"/>
    </inertial>
    <visual>
      <origin rpy="0 0 0" xyz="-0.039585 0.06105 -0.022478"/>
      <geometry>
        <mesh filename="/assembly_simple_description/meshes/assembly_simplyv3_backup_Component6_Mirror__Mirror__v1_1.obj" scale="0.001 0.001 0.001"/>
      </geometry>
      <material name="silver"/>
    </visual>
    <collision>
      <origin rpy="0 0 0" xyz="-0.039585 0.06105 -0.022478"/>
      <geometry>
        <mesh filename="/assembly_simple_description/meshes/assembly_simplyv3_backup_Component6_Mirror__Mirror__v1_1.obj" scale="0.001 0.001 0.001"/>
      </geometry>
    </collision>
  </link>
  <link name="assembly_simplyv3_backup_Component6_Mirror___1__v1_1">
    <inertial>
      <origin rpy="0 0 0" xyz="0.014097947947670164 -0.031213496015972755 8.433709991042052e-05"/>
      <mass value="0.012949520700092825"/>
      <inertia ixx="6e-06" ixy="1e-06" ixz="-0.0" iyy="1e-06" iyz="0.0" izz="7e-06"/>
    </inertial>
    <visual>
      <origin rpy="0 0 0" xyz="-0.039585 -0.06105 -0.022478"/>
      <geometry>
        <mesh filename="/assembly_simple_description/meshes/assembly_simplyv3_backup_Component6_Mirror___1__v1_1.obj" scale="0.001 0.001 0.001"/>
      </geometry>
      <material name="silver"/>
    </visual>
    <collision>
      <origin rpy="0 0 0" xyz="-0.039585 -0.06105 -0.022478"/>
      <geometry>
        <mesh filename="/assembly_simple_description/meshes/assembly_simplyv3_backup_Component6_Mirror___1__v1_1.obj" scale="0.001 0.001 0.001"/>
      </geometry>
    </collision>
  </link>
  <link name="assembly_simplyv3_backup_lowerleg_left_v2_v1_1">
    <inertial>
      <origin rpy="0 0 0" xyz="0.0026345540282930735 0.016520008906610893 0.0005581709036688552"/>
      <mass value="0.0026700130710144935"/>
      <inertia ixx="1e-06" ixy="-0.0" ixz="-0.0" iyy="0.0" iyz="-0.0" izz="1e-06"/>
    </inertial>
    <visual>
      <origin rpy="0 0 0" xyz="0.045235 -0.01295 -0.022628"/>
      <geometry>
        <mesh filename="/assembly_simple_description/meshes/assembly_simplyv3_backup_lowerleg_left_v2_v1_1.obj" scale="0.001 0.001 0.001"/>
      </geometry>
      <material name="silver"/>
    </visual>
    <collision>
      <origin rpy="0 0 0" xyz="0.045235 -0.01295 -0.022628"/>
      <geometry>
        <mesh filename="/assembly_simple_description/meshes/assembly_simplyv3_backup_lowerleg_left_v2_v1_1.obj" scale="0.001 0.001 0.001"/>
      </geometry>
    </collision>
  </link>
  <link name="assembly_simplyv3_backup_lowerleg_left_v2_Mirror__v1_1">
    <inertial>
      <origin rpy="0 0 0" xyz="-0.0026345540282929486 0.016520008906611126 0.0005581709036687962"/>
      <mass value="0.0026700130710144944"/>
      <inertia ixx="1e-06" ixy="0.0" ixz="0.0" iyy="0.0" iyz="-0.0" izz="1e-06"/>
    </inertial>
    <visual>
      <origin rpy="0 0 0" xyz="-0.045335 -0.01295 -0.022628"/>
      <geometry>
        <mesh filename="/assembly_simple_description/meshes/assembly_simplyv3_backup_lowerleg_left_v2_Mirror__v1_1.obj" scale="0.001 0.001 0.001"/>
      </geometry>
      <material name="silver"/>
    </visual>
    <collision>
      <origin rpy="0 0 0" xyz="-0.045335 -0.01295 -0.022628"/>
      <geometry>
        <mesh filename="/assembly_simple_description/meshes/assembly_simplyv3_backup_lowerleg_left_v2_Mirror__v1_1.obj" scale="0.001 0.001 0.001"/>
      </geometry>
    </collision>
  </link>
  <link name="assembly_simplyv3_backup_lowerleg_left_v2_Mirror___1__v1_1">
    <inertial>
      <origin rpy="0 0 0" xyz="0.002634554028293025 -0.016520008906610838 0.0005581709036688275"/>
      <mass value="0.0026700130710144944"/>
      <inertia ixx="1e-06" ixy="0.0" ixz="-0.0" iyy="0.0" iyz="0.0" izz="1e-06"/>
    </inertial>
    <visual>
      <origin rpy="0 0 0" xyz="0.045235 0.01295 -0.022628"/>
      <geometry>
        <mesh filename="/assembly_simple_description/meshes/assembly_simplyv3_backup_lowerleg_left_v2_Mirror___1__v1_1.obj" scale="0.001 0.001 0.001"/>
      </geometry>
      <material name="silver"/>
    </visual>
    <collision>
      <origin rpy="0 0 0" xyz="0.045235 0.01295 -0.022628"/>
      <geometry>
        <mesh filename="/assembly_simple_description/meshes/assembly_simplyv3_backup_lowerleg_left_v2_Mirror___1__v1_1.obj" scale="0.001 0.001 0.001"/>
      </geometry>
    </collision>
  </link>
  <link name="assembly_simplyv3_backup_lowerleg_left_v2_Mirror__Mirror__v1_1">
    <inertial>
      <origin rpy="0 0 0" xyz="-0.0026345540282930457 -0.01652000890661092 0.0005581709036688448"/>
      <mass value="0.0026700130710144935"/>
      <inertia ixx="1e-06" ixy="-0.0" ixz="0.0" iyy="0.0" iyz="0.0" izz="1e-06"/>
    </inertial>
    <visual>
      <origin rpy="0 0 0" xyz="-0.045335 0.01295 -0.022628"/>
      <geometry>
        <mesh filename="/assembly_simple_description/meshes/assembly_simplyv3_backup_lowerleg_left_v2_Mirror__Mirror__v1_1.obj" scale="0.001 0.001 0.001"/>
      </geometry>
      <material name="silver"/>
    </visual>
    <collision>
      <origin rpy="0 0 0" xyz="-0.045335 0.01295 -0.022628"/>
      <geometry>
        <mesh filename="/assembly_simple_description/meshes/assembly_simplyv3_backup_lowerleg_left_v2_Mirror__Mirror__v1_1.obj" scale="0.001 0.001 0.001"/>
      </geometry>
    </collision>
  </link>
  <joint name="Revolute 1" type="revolute">
    <origin rpy="0 0 0" xyz="-0.026925 0.05165 0.02138"/>
    <parent link="base_link"/>
    <child link="assembly_simplyv3_backup_hip_L_simple_v2_v1_1"/>
    <axis xyz="-0.0 1.0 -0.0"/>
    <limit effort="0.18" lower="0" upper="3.14159" velocity="10.47"/>
    <initial_position value="1.5708"/>
  </joint>
  <joint name="Revolute 2" type="revolute">
    <origin rpy="0 0 0" xyz="0.026925 -0.05165 0.02138"/>
    <parent link="base_link"/>
    <child link="assembly_simplyv3_backup_hip_L_simple_v2_Mirror__Mirror__v1_1"/>
    <axis xyz="0.0 -1.0 -0.0"/>
    <limit effort="0.18" lower="0" upper="3.14159" velocity="10.47"/>
    <initial_position value="1.5708"/>
  </joint>
  <joint name="Revolute 3" type="revolute">
    <origin rpy="0 0 0" xyz="0.026925 0.05165 0.02138"/>
    <parent link="base_link"/>
    <child link="assembly_simplyv3_backup_hip_L_simple_v2_Mirror__v1_1"/>
    <axis xyz="-0.0 -1.0 0.0"/>
    <limit effort="0.18" lower="0" upper="3.14159" velocity="10.47"/>
    <initial_position value="1.5708"/>
  </joint>
  <joint name="Revolute 4" type="revolute">
    <origin rpy="0 0 0" xyz="-0.026925 -0.05165 0.02138"/>
    <parent link="base_link"/>
    <child link="assembly_simplyv3_backup_hip_L_simple_v2_Mirror___1__v1_1"/>
    <axis xyz="0.0 1.0 0.0"/>
    <limit effort="0.18" lower="0" upper="3.14159" velocity="10.47"/>
    <initial_position value="1.5708"/>
  </joint>
  <joint name="Revolute 5" type="revolute">
    <origin rpy="0 0 0" xyz="-0.01256 0.0094 0.001098"/>
    <parent link="assembly_simplyv3_backup_hip_L_simple_v2_v1_1"/>
    <child link="assembly_simplyv3_backup_Component6_v1_1"/>
    <axis xyz="1.0 -0.0 0.0"/>
    <limit effort="0.18" lower="0" upper="3.14159" velocity="10.47"/>
    <initial_position value="0.0"/>
  </joint>
  <joint name="Revolute 6" type="revolute">
    <origin rpy="0 0 0" xyz="-0.01256 -0.0094 0.001098"/>
    <parent link="assembly_simplyv3_backup_hip_L_simple_v2_Mirror___1__v1_1"/>
    <child link="assembly_simplyv3_backup_Component6_Mirror__v1_1"/>
    <axis xyz="-1.0 -0.0 -0.0"/>
    <limit effort="0.18" lower="0" upper="3.14159" velocity="10.47"/>
    <initial_position value="0.0"/>
  </joint>
  <joint name="Revolute 7" type="revolute">
    <origin rpy="0 0 0" xyz="0.01266 -0.0094 0.001098"/>
    <parent link="assembly_simplyv3_backup_hip_L_simple_v2_Mirror__Mirror__v1_1"/>
    <child link="assembly_simplyv3_backup_Component6_Mirror__Mirror__v1_1"/>
    <axis xyz="1.0 -0.0 -0.0"/>
    <limit effort="0.18" lower="0" upper="3.14159" velocity="10.47"/>
    <initial_position value="0.0"/>
  </joint>
  <joint name="Revolute 8" type="revolute">
    <origin rpy="0 0 0" xyz="0.01266 0.0094 0.001098"/>
    <parent link="assembly_simplyv3_backup_hip_L_simple_v2_Mirror__v1_1"/>
    <child link="assembly_simplyv3_backup_Component6_Mirror___1__v1_1"/>
    <axis xyz="-1.0 -0.0 0.0"/>
    <limit effort="0.18" lower="0" upper="3.14159" velocity="10.47"/>
    <initial_position value="0.0"/>
  </joint>
  <joint name="Revolute 9" type="revolute">
    <origin rpy="0 0 0" xyz="-0.00575 -0.0481 0.00015"/>
    <parent link="assembly_simplyv3_backup_Component6_v1_1"/>
    <child link="assembly_simplyv3_backup_lowerleg_left_v2_v1_1"/>
    <axis xyz="1.0 0.0 0.0"/>
    <limit effort="0.18" lower="0" upper="3.14159" velocity="10.47"/>
    <initial_position value="0.0"/>
  </joint>
  <joint name="Revolute 10" type="revolute">
    <origin rpy="0 0 0" xyz="0.00575 -0.0481 0.00015"/>
    <parent link="assembly_simplyv3_backup_Component6_Mirror___1__v1_1"/>
    <child link="assembly_simplyv3_backup_lowerleg_left_v2_Mirror__v1_1"/>
    <axis xyz="1.0 -0.0 -0.0"/>
    <limit effort="0.18" lower="0" upper="3.14159" velocity="10.47"/>
    <initial_position value="0.0"/>
  </joint>
  <joint name="Revolute 11" type="revolute">
    <origin rpy="0 0 0" xyz="-0.00575 0.0481 0.00015"/>
    <parent link="assembly_simplyv3_backup_Component6_Mirror__v1_1"/>
    <child link="assembly_simplyv3_backup_lowerleg_left_v2_Mirror___1__v1_1"/>
    <axis xyz="-1.0 0.0 -0.0"/>
    <limit effort="0.18" lower="0" upper="3.14159" velocity="10.47"/>
    <initial_position value="0.0"/>
  </joint>
  <joint name="Revolute 12" type="revolute">
    <origin rpy="0 0 0" xyz="0.00575 0.0481 0.00015"/>
    <parent link="assembly_simplyv3_backup_Component6_Mirror__Mirror__v1_1"/>
    <child link="assembly_simplyv3_backup_lowerleg_left_v2_Mirror__Mirror__v1_1"/>
    <axis xyz="-1.0 -0.0 0.0"/>
    <limit effort="0.18" lower="0" upper="3.14159" velocity="10.47"/>
    <initial_position value="0.0"/>
  </joint>
</robot>
